<?xml version="1.0" ?>
<!-- =================================================================================== -->
<!-- |    This document was autogenerated by xacro from arm.xacro                      | -->
<!-- |    EDITING THIS FILE BY HAND IS NOT RECOMMENDED                                 | -->
<!-- =================================================================================== -->
<!-- Differential drive robot -->
<robot name="diff_robot" xmlns:xacro="http://www.ros.org/wiki/xacro">
  <link name="world"/>
  <!-- Base of a robot -->
  <link name="arm1">
    <origin rpy="0 0 0" xyz="0 0 0.3"/>
    <inertial>
      <mass value="0.8"/>
      <inertia ixx="0.02418" ixy="0" ixz="0" iyy="0.02418" iyz="0" izz="0.00036"/>
    </inertial>
    <collision>
      <origin rpy="0 0 0" xyz="0 0 0.3"/>
      <geometry>
        <cylinder length="0.6" radius="0.03"/>
      </geometry>
    </collision>
    <visual>
      <origin rpy="0 0 0" xyz="0 0 0.3"/>
      <geometry>
        <cylinder length="0.6" radius="0.03"/>
      </geometry>
    </visual>
  </link>
  <joint name="base_joint" type="fixed">
    <axis xyz="0 0 0"/>
    <origin rpy="0 0 0" xyz="0 0 0"/>
    <parent link="world"/>
    <child link="arm1"/>
    <limit effort="1000" lower="0" upper="6.28" velocity="100"/>
    <axis rpy="0 0 0" xyz="0 0 0"/>
    <joint_properties damping="1.0" friction="1.0"/>
  </joint>
  <link name="arm2">
    <origin rpy="0 0 0" xyz="0 0 0.18"/>
    <inertial>
      <mass value="0.4"/>
      <inertia ixx="0.00842333333333" ixy="0" ixz="0" iyy="0.00842333333333" iyz="0" izz="0.00018"/>
    </inertial>
    <collision>
      <origin rpy="0 0 0" xyz="0 0 0.18"/>
      <geometry>
        <cylinder length="0.5" radius="0.03"/>
      </geometry>
    </collision>
    <visual>
      <origin rpy="0 0 0" xyz="0 0 0.18"/>
      <geometry>
        <cylinder length="0.5" radius="0.03"/>
      </geometry>
    </visual>
  </link>
  <joint name="base_arm2_joint" type="continuous">
    <axis xyz="0 1 0"/>
    <origin rpy="0 0 0" xyz="0 0.07 0.55"/>
    <parent link="arm1"/>
    <child link="arm2"/>
    <limit effort="1000" lower="0" upper="6.28" velocity="100"/>
    <axis rpy="0 0 0" xyz="0 0.07 0.55"/>
    <joint_properties damping="1.0" friction="1.0"/>
  </joint>
  <link name="arm3">
    <origin rpy="0 0 0" xyz="0 0 0.15"/>
    <inertial>
      <mass value="0.4"/>
      <inertia ixx="0.00542333333333" ixy="0" ixz="0" iyy="0.00542333333333" iyz="0" izz="0.00018"/>
    </inertial>
    <collision>
      <origin rpy="0 0 0" xyz="0 0 0.15"/>
      <geometry>
        <cylinder length="0.4" radius="0.03"/>
      </geometry>
    </collision>
    <visual>
      <origin rpy="0 0 0" xyz="0 0 0.15"/>
      <geometry>
        <cylinder length="0.4" radius="0.03"/>
      </geometry>
    </visual>
  </link>
  <joint name="base_arm3_joint" type="continuous">
    <axis xyz="0 1 0"/>
    <origin rpy="0 0 0" xyz="0 0.07 0.45"/>
    <parent link="arm2"/>
    <child link="arm3"/>
    <limit effort="1000" lower="0" upper="6.28" velocity="100"/>
    <axis rpy="0 0 0" xyz="0 0.07 0.45"/>
    <joint_properties damping="1.0" friction="1.0"/>
  </joint>
</robot>

